<?xml version="1.0" ?>

<robot name="dg2f">
  <link name="l_base">
    <!-- <inertial>
      <mass value="0.451" />
    </inertial> -->
    <visual>
      <origin xyz="0 0 0" rpy="0 0 3.14" />
      <geometry>
        <mesh filename="package://dg2f_description/meshes/dg2f/visual/l_base.dae" />
      </geometry>
      <material>
        <color rgba="0.03 0.03 0.03 1.0"/>
      </material>
    </visual>
    <collision>
      <origin xyz="0 0 0" rpy="0 0 3.14" />
      <geometry>
        <mesh filename="package://dg2f_description/meshes/dg2f/collision/l_base.stl" />
      </geometry>
    </collision>
  </link>

  <link name="l_1_1">
    <!-- <inertial>
      <mass value="0.046" />
    </inertial> -->
    <visual>
      <origin xyz="0 0 0" rpy="0 0 0" />
      <geometry>
        <mesh filename="package://dg2f_description/meshes/dg2f/visual/l_1.dae" />
      </geometry>
      <material>
        <color rgba="0.07 0.07 0.07 1.0"/>
      </material>
    </visual>
    <collision>
      <origin xyz="0 0 0" rpy="0 0 0" />
      <geometry>
        <mesh filename="package://dg2f_description/meshes/dg2f/collision/l_1.stl" />
      </geometry>
    </collision>
  </link>
  <joint name="j_1_1" type="revolute">
    <origin xyz="0 0.00785 0.038" rpy="0.0 0.0 0.0" />
    <parent link="l_base" />
    <child link="l_1_1" />
    <axis xyz="0 1 0" />
    <limit lower="-1.5708" upper="1.5708" effort="7.644" velocity="3.141592653589793" />
  </joint>
  <link name="l_1_2">
    <!-- <inertial>
      <mass value="0.027" />
    </inertial> -->
    <visual>
      <origin xyz="0 0 0" rpy="0 0 0" />
      <geometry>
        <mesh filename="package://dg2f_description/meshes/dg2f/visual/l_2.dae" />
      </geometry>
      <material>
        <color rgba="0.07 0.07 0.07 1.0"/>
      </material>
    </visual>
    <collision>
      <origin xyz="0 0 0" rpy="0 0 0" />
      <geometry>
        <mesh filename="package://dg2f_description/meshes/dg2f/collision/l_2.stl" />
      </geometry>
    </collision>
  </link>
  <joint name="j_1_2" type="revolute">
    <origin xyz="0 0.0354 0.02905" rpy="-1.5708 0.0 0.0" />
    <parent link="l_1_1" />
    <child link="l_1_2" />
    <axis xyz="1 0 0" />
    <limit lower="0" upper="3.141593" effort="7.644" velocity="3.141592653589793" />
  </joint>
  <link name="l_1_3">
    <!-- <inertial>
      <mass value="0.027" />
    </inertial> -->
    <visual>
      <origin xyz="0 0 0" rpy="0 0 0" />
      <geometry>
        <mesh filename="package://dg2f_description/meshes/dg2f/visual/l_3.dae" />
      </geometry>
      <material>
        <color rgba="0.07 0.07 0.07 1.0"/>
      </material>
    </visual>
    <collision>
      <origin xyz="0 0 0" rpy="0 0 0" />
      <geometry>
        <mesh filename="package://dg2f_description/meshes/dg2f/collision/l_3.stl" />
      </geometry>
    </collision>
  </link>
  <joint name="j_1_3" type="revolute">
    <origin xyz="0 0 0.043645" rpy="0.0 0.0 0.0" />
    <parent link="l_1_2" />
    <child link="l_1_3" />
    <axis xyz="1 0 0" />
    <limit lower="-1.5708" upper="1.5708" effort="7.644" velocity="3.141592653589793" />
  </joint>
  <link name="l_1_4">
    <!-- <inertial>
      <mass value="0.041" />
    </inertial> -->
    <visual>
      <origin xyz="0 0 0" rpy="0 0 0" />
      <geometry>
        <mesh filename="package://dg2f_description/meshes/dg2f/visual/l_tip.dae" />
      </geometry>
      <material>
        <color rgba="0.07 0.07 0.07 1.0"/>
      </material>
    </visual>
    <collision>
      <origin xyz="0 0 0" rpy="0 0 0" />
      <geometry>
        <mesh filename="package://dg2f_description/meshes/dg2f/collision/l_tip.stl" />
      </geometry>
    </collision>
  </link>
  <joint name="j_1_4" type="fixed">
    <origin xyz="0 0 0.031314" rpy="0.0 0.0 0.0" />
    <parent link="l_1_3" />
    <child link="l_1_4" />
    <axis xyz="0 0 1" />
  </joint>

  <link name="l_2_1">
    <!-- <inertial>
      <mass value="0.046" />
    </inertial> -->
    <visual>
      <origin xyz="0 0 0" rpy="0 0 0" />
      <geometry>
        <mesh filename="package://dg2f_description/meshes/dg2f/visual/l_1.dae" />
      </geometry>
      <material>
        <color rgba="0.07 0.07 0.07 1.0"/>
      </material>
    </visual>
    <collision>
      <origin xyz="0 0 0" rpy="0 0 0" />
      <geometry>
        <mesh filename="package://dg2f_description/meshes/dg2f/collision/l_1.stl" />
      </geometry>
    </collision>
  </link>
  <joint name="j_2_1" type="revolute">
    <origin xyz="0 -0.00785 0.038" rpy="0.0 0.0 3.141593" />
    <parent link="l_base" />
    <child link="l_2_1" />
    <axis xyz="0 1 0" />
    <limit lower="-1.5708" upper="1.5708" effort="7.644" velocity="3.141592653589793" />
  </joint>
  <link name="l_2_2">
    <!-- <inertial>
      <mass value="0.027" />
    </inertial> -->
    <visual>
      <origin xyz="0 0 0" rpy="0 0 0" />
      <geometry>
        <mesh filename="package://dg2f_description/meshes/dg2f/visual/l_2.dae" />
      </geometry>
      <material>
        <color rgba="0.07 0.07 0.07 1.0"/>
      </material>
    </visual>
    <collision>
      <origin xyz="0 0 0" rpy="0 0 0" />
      <geometry>
        <mesh filename="package://dg2f_description/meshes/dg2f/collision/l_2.stl" />
      </geometry>
    </collision>
  </link>
  <joint name="j_2_2" type="revolute">
    <origin xyz="0 0.0354 0.02905" rpy="-1.5708 0.0 0.0" />
    <parent link="l_2_1" />
    <child link="l_2_2" />
    <axis xyz="1 0 0" />
    <limit lower="0" upper="3.141593" effort="7.644" velocity="3.141592653589793" />
  </joint>
  <link name="l_2_3">
    <!-- <inertial>
      <mass value="0.027" />
    </inertial> -->
    <visual>
      <origin xyz="0 0 0" rpy="0 0 0" />
      <geometry>
        <mesh filename="package://dg2f_description/meshes/dg2f/visual/l_3.dae" />
      </geometry>
      <material>
        <color rgba="0.07 0.07 0.07 1.0"/>
      </material>
    </visual>
    <collision>
      <origin xyz="0 0 0" rpy="0 0 0" />
      <geometry>
        <mesh filename="package://dg2f_description/meshes/dg2f/collision/l_3.stl" />
      </geometry>
    </collision>
  </link>
  <!--joint 1-->
  <joint name="j_2_3" type="revolute">
    <origin xyz="0 0 0.043645" rpy="0.0 0.0 0.0" />
    <parent link="l_2_2" />
    <child link="l_2_3" />
    <axis xyz="1 0 0" />
    <limit lower="-1.5708" upper="1.5708" effort="7.644" velocity="3.141592653589793" />
  </joint>
  <link name="l_2_4">
    <!-- <inertial>
      <mass value="0.041" />
    </inertial> -->
    <visual>
      <origin xyz="0 0 0" rpy="0 0 0" />
      <geometry>
        <mesh filename="package://dg2f_description/meshes/dg2f/visual/l_tip.dae" />
      </geometry>
      <material>
        <color rgba="0.07 0.07 0.07 1.0"/>
      </material>
    </visual>
    <collision>
      <origin xyz="0 0 0" rpy="0 0 0" />
      <geometry>
        <mesh filename="package://dg2f_description/meshes/dg2f/collision/l_tip.stl" />
      </geometry>
    </collision>
  </link>
  <joint name="j_2_4" type="fixed">
    <origin xyz="0 0 0.031314" rpy="0.0 0.0 0.0" />
    <parent link="l_2_3" />
    <child link="l_2_4" />
    <axis xyz="0 0 1" />
  </joint>
</robot>
